Workbook
Name H: Sheet1!$G:$G

Sheet Sheet1
F5: SIBERIA HOSTEL
F6: MESS BILL | G6: 2025 | H6: AUGUST
E8: Opening Stock | F8: 0 | G8: Salary | H8: 49000
E9: Total Expences | F9: =1750*97 -> 169750 | G9: Allowance | H9: 500
E10: Extras | F10: 1680 | G10: MISCELLANEOUS | H10: 0
E11: Closing Stock | F11: 2000 | G11: BONUS | H11: 15000
E12: Per day charge | F12: 89
E13: Est. Charge | F13: 400
C16: SL.NO | D16: NAME | E16: DEPARTMENT | F16: EST | G16: TOTAL AMOUNT | H16: TOTAL DAYS | I16: MESSCUT | J16: EFFECTIVE DAYS | K16: EXTRAS&GUEST | L16: LATE MESS | M16: FINAL
C17: 1 | D17: AKSHAY | E17: DST | F17: =$F$13 -> 400 | G17: =J17*$F$12+F17+Sheet1!$K17+Sheet1!$L17 -> 2527.1 | H17: 26 | I17: 3 | J17: =H17-(I17*0.7) -> 23.9 | M17: =Sheet1!$F17+$F$12*Sheet1!$J17+Sheet1!$K17+Sheet1!$L17 -> 2527.1
C18: =C17+1 -> 2 | D18: AMAL KIRAN | E18: DST | F18: =$F$13 -> 400 | G18: =J18*$F$12+F18+Sheet1!$K18+Sheet1!$L18 -> 2714 | H18: 26 | J18: =H18-(I18*0.7) -> 26 | M18: =Sheet1!$F18+$F$12*Sheet1!$J18+Sheet1!$K18+Sheet1!$L18 -> 2714
C19: =C18+1 -> 3 | D19: AMBAREESH V | E19: DST | F19: =$F$13 -> 400 | G19: =J19*$F$12+F19+Sheet1!$K19+Sheet1!$L19 -> 2714 | H19: 26 | J19: =H19-(I19*0.7) -> 26 | M19: =Sheet1!$F19+$F$12*Sheet1!$J19+Sheet1!$K19+Sheet1!$L19 -> 2714
C20: =C19+1 -> 4 | D20: ANIRUDH | E20: DST | F20: =$F$13 -> 400 | G20: =J20*$F$12+F20+Sheet1!$K20+Sheet1!$L20 -> 2714 | H20: 26 | J20: =H20-(I20*0.7) -> 26 | M20: =Sheet1!$F20+$F$12*Sheet1!$J20+Sheet1!$K20+Sheet1!$L20 -> 2714
C21: =C20+1 -> 5 | D21: ASHBIN SANTHOSH | E21: DST | F21: =$F$13 -> 400 | G21: =J21*$F$12+F21+Sheet1!$K21+Sheet1!$L21 -> 2714 | H21: 26 | J21: =H21-(I21*0.7) -> 26 | M21: =Sheet1!$F21+$F$12*Sheet1!$J21+Sheet1!$K21+Sheet1!$L21 -> 2714
C22: =C21+1 -> 6 | D22: ASHISH SUDHEER | E22: DST | F22: =$F$13 -> 400 | G22: =J22*$F$12+F22+Sheet1!$K22+Sheet1!$L22 -> 2714 | H22: 26 | J22: =H22-(I22*0.7) -> 26 | M22: =Sheet1!$F22+$F$12*Sheet1!$J22+Sheet1!$K22+Sheet1!$L22 -> 2714
C23: =C22+1 -> 7 | D23: ASHWIN THAMBAN K V | E23: DST | F23: =$F$13 -> 400 | G23: =J23*$F$12+F23+Sheet1!$K23+Sheet1!$L23 -> 2714 | H23: 26 | J23: =H23-(I23*0.7) -> 26 | M23: =Sheet1!$F23+$F$12*Sheet1!$J23+Sheet1!$K23+Sheet1!$L23 -> 2714
C24: =C23+1 -> 8 | D24: EDWIN NADAKKALAN | E24: DST | F24: =$F$13 -> 400 | G24: =J24*$F$12+F24+Sheet1!$K24+Sheet1!$L24 -> 2714 | H24: 26 | J24: =H24-(I24*0.7) -> 26 | M24: =Sheet1!$F24+$F$12*Sheet1!$J24+Sheet1!$K24+Sheet1!$L24 -> 2714
C25: =C24+1 -> 9 | D25: HARIDEEP | E25: DST | F25: =$F$13 -> 400 | G25: =J25*$F$12+F25+Sheet1!$K25+Sheet1!$L25 -> 2714 | H25: 26 | J25: =H25-(I25*0.7) -> 26 | M25: =Sheet1!$F25+$F$12*Sheet1!$J25+Sheet1!$K25+Sheet1!$L25 -> 2714
C26: =C25+1 -> 10 | D26: KRISHNA KUMAR | E26: DST | F26: =$F$13 -> 400 | G26: =J26*$F$12+F26+Sheet1!$K26+Sheet1!$L26 -> 2714 | H26: 26 | J26: =H26-(I26*0.7) -> 26 | M26: =Sheet1!$F26+$F$12*Sheet1!$J26+Sheet1!$K26+Sheet1!$L26 -> 2714
C27: =C26+1 -> 11 | D27: MANUVAL MATHEW | E27: DST | F27: =$F$13 -> 400 | G27: =J27*$F$12+F27+Sheet1!$K27+Sheet1!$L27 -> 2714 | H27: 26 | J27: =H27-(I27*0.7) -> 26 | M27: =Sheet1!$F27+$F$12*Sheet1!$J27+Sheet1!$K27+Sheet1!$L27 -> 2714
C28: =C27+1 -> 12 | D28: NOUBIL MAJID | E28: DST | F28: =$F$13 -> 400 | G28: =J28*$F$12+F28+Sheet1!$K28+Sheet1!$L28 -> 2714 | H28: 26 | J28: =H28-(I28*0.7) -> 26 | M28: =Sheet1!$F28+$F$12*Sheet1!$J28+Sheet1!$K28+Sheet1!$L28 -> 2714
C29: =C28+1 -> 13 | D29: SADATH | E29: DST | F29: =$F$13 -> 400 | G29: =J29*$F$12+F29+Sheet1!$K29+Sheet1!$L29 -> 2277.9 | H29: 26 | I29: 7 | J29: =H29-(I29*0.7) -> 21.1 | M29: =Sheet1!$F29+$F$12*Sheet1!$J29+Sheet1!$K29+Sheet1!$L29 -> 2277.9
C30: =C29+1 -> 14 | D30: SIDHARTH A | E30: DST | F30: =$F$13 -> 400 | G30: =J30*$F$12+F30+Sheet1!$K30+Sheet1!$L30 -> 2714 | H30: 26 | J30: =H30-(I30*0.7) -> 26 | M30: =Sheet1!$F30+$F$12*Sheet1!$J30+Sheet1!$K30+Sheet1!$L30 -> 2714
C31: =C30+1 -> 15 | D31: SHANE | E31: DST | F31: =$F$13 -> 400 | G31: =J31*$F$12+F31+Sheet1!$K31+Sheet1!$L31 -> 2091 | H31: 26 | I31: 10 | J31: =H31-(I31*0.7) -> 19 | M31: =Sheet1!$F31+$F$12*Sheet1!$J31+Sheet1!$K31+Sheet1!$L31 -> 2091
C32: =C31+1 -> 16 | D32: AKHIL | E32: DST | F32: =$F$13 -> 400 | G32: =J32*$F$12+F32+Sheet1!$K32+Sheet1!$L32 -> 2714 | H32: 26 | J32: =H32-(I32*0.7) -> 26 | M32: =Sheet1!$F32+$F$12*Sheet1!$J32+Sheet1!$K32+Sheet1!$L32 -> 2714
C33: =C32+1 -> 17 | D33: Peyoosh | E33: DST | F33: =$F$13 -> 400 | G33: =J33*$F$12+F33+Sheet1!$K33+Sheet1!$L33 -> 2714 | H33: 26 | J33: =H33-(I33*0.7) -> 26 | M33: =Sheet1!$F33+$F$12*Sheet1!$J33+Sheet1!$K33+Sheet1!$L33 -> 2714
C34: =C33+1 -> 18 | D34: Adeeb | E34: DST | F34: =$F$13 -> 400 | G34: =J34*$F$12+F34+Sheet1!$K34+Sheet1!$L34 -> 2714 | H34: 26 | J34: =H34-(I34*0.7) -> 26 | M34: =Sheet1!$F34+$F$12*Sheet1!$J34+Sheet1!$K34+Sheet1!$L34 -> 2714
C35: =C34+1 -> 19 | D35: Abhishek .S | E35: DST | F35: =$F$13 -> 400 | G35: =J35*$F$12+F35+Sheet1!$K35+Sheet1!$L35 -> 2464.8 | H35: 26 | I35: 4 | J35: =H35-(I35*0.7) -> 23.2 | M35: =Sheet1!$F35+$F$12*Sheet1!$J35+Sheet1!$K35+Sheet1!$L35 -> 2464.8
C36: =C35+1 -> 20 | D36: Abhishek VN | E36: DST | F36: =$F$13 -> 400 | G36: =J36*$F$12+F36+Sheet1!$K36+Sheet1!$L36 -> 2714 | H36: 26 | J36: =H36-(I36*0.7) -> 26 | M36: =Sheet1!$F36+$F$12*Sheet1!$J36+Sheet1!$K36+Sheet1!$L36 -> 2714
C37: =C36+1 -> 21 | D37: Adarsh T Biju | E37: DST | F37: =$F$13 -> 400 | G37: =J37*$F$12+F37+Sheet1!$K37+Sheet1!$L37 -> 2277.9 | H37: 26 | I37: 7 | J37: =H37-(I37*0.7) -> 21.1 | M37: =Sheet1!$F37+$F$12*Sheet1!$J37+Sheet1!$K37+Sheet1!$L37 -> 2277.9
C38: =C37+1 -> 22 | D38: Adith S Vinod | E38: DST | F38: =$F$13 -> 400 | G38: =J38*$F$12+F38+Sheet1!$K38+Sheet1!$L38 -> 2714 | H38: 26 | J38: =H38-(I38*0.7) -> 26 | M38: =Sheet1!$F38+$F$12*Sheet1!$J38+Sheet1!$K38+Sheet1!$L38 -> 2714
C39: =C38+1 -> 23 | D39: Advaith Ullas | E39: DST | F39: =$F$13 -> 400 | G39: =J39*$F$12+F39+Sheet1!$K39+Sheet1!$L39 -> 2714 | H39: 26 | J39: =H39-(I39*0.7) -> 26 | M39: =Sheet1!$F39+$F$12*Sheet1!$J39+Sheet1!$K39+Sheet1!$L39 -> 2714
C40: =C39+1 -> 24 | D40: Akhil Jose | E40: DST | F40: =$F$13 -> 400 | G40: =J40*$F$12+F40+Sheet1!$K40+Sheet1!$L40 -> 2153.3 | H40: 26 | I40: 9 | J40: =H40-(I40*0.7) -> 19.7 | M40: =Sheet1!$F40+$F$12*Sheet1!$J40+Sheet1!$K40+Sheet1!$L40 -> 2153.3
C41: =C40+1 -> 25 | D41: Anandu K | E41: DST | F41: =$F$13 -> 400 | G41: =J41*$F$12+F41+Sheet1!$K41+Sheet1!$L41 -> 2527.1 | H41: 26 | I41: 3 | J41: =H41-(I41*0.7) -> 23.9 | M41: =Sheet1!$F41+$F$12*Sheet1!$J41+Sheet1!$K41+Sheet1!$L41 -> 2527.1
C42: =C41+1 -> 26 | D42: Devadath Uday P.K | E42: DST | F42: =$F$13 -> 400 | G42: =J42*$F$12+F42+Sheet1!$K42+Sheet1!$L42 -> 2714 | H42: 26 | J42: =H42-(I42*0.7) -> 26 | M42: =Sheet1!$F42+$F$12*Sheet1!$J42+Sheet1!$K42+Sheet1!$L42 -> 2714
C43: =C42+1 -> 27 | D43: Haridevan.v | E43: DST | F43: =$F$13 -> 400 | G43: =J43*$F$12+F43+Sheet1!$K43+Sheet1!$L43 -> 2651.7 | H43: 26 | I43: 1 | J43: =H43-(I43*0.7) -> 25.3 | M43: =Sheet1!$F43+$F$12*Sheet1!$J43+Sheet1!$K43+Sheet1!$L43 -> 2651.7
C44: =C43+1 -> 28 | D44: Rohith SANTHOSH | E44: DST | F44: =$F$13 -> 400 | G44: =J44*$F$12+F44+Sheet1!$K44+Sheet1!$L44 -> 2714 | H44: 26 | J44: =H44-(I44*0.7) -> 26 | M44: =Sheet1!$F44+$F$12*Sheet1!$J44+Sheet1!$K44+Sheet1!$L44 -> 2714
C45: =C44+1 -> 29 | D45: Ismail V.J | E45: DST | F45: =$F$13 -> 400 | G45: =J45*$F$12+F45+Sheet1!$K45+Sheet1!$L45 -> 2091 | H45: 26 | I45: 10 | J45: =H45-(I45*0.7) -> 19 | M45: =Sheet1!$F45+$F$12*Sheet1!$J45+Sheet1!$K45+Sheet1!$L45 -> 2091
C46: =C45+1 -> 30 | D46: Josphin Devassy | E46: DST | F46: =$F$13 -> 400 | G46: =J46*$F$12+F46+Sheet1!$K46+Sheet1!$L46 -> 1468 | H46: 26 | I46: 20 | J46: =H46-(I46*0.7) -> 12 | M46: =Sheet1!$F46+$F$12*Sheet1!$J46+Sheet1!$K46+Sheet1!$L46 -> 1468
C47: =C46+1 -> 31 | D47: Jyothis Krishna A.K | E47: DST | F47: =$F$13 -> 400 | G47: =J47*$F$12+F47+Sheet1!$K47+Sheet1!$L47 -> 2714 | H47: 26 | J47: =H47-(I47*0.7) -> 26 | M47: =Sheet1!$F47+$F$12*Sheet1!$J47+Sheet1!$K47+Sheet1!$L47 -> 2714
...

Sheet Sheet2
F2: SIBERIA HOSTEL
F3: MESS BILL | G3: 2025 | H3: AUGUST
E4: Opening Stock | F4: 0 | G4: Salary | H4: 49000
E5: Total Expences | F5: =2045*97 -> 198365 | G5: Allowance | H5: 6000
E6: Extras | F6: 1260 | G6: MISCELLANEOUS | H6: 4500
E7: Closing Stock | F7: 2000 | G7: BONUS | H7: 15000
E8: Per day charge | F8: 89
E9: Est. Charge | F9: 400
D14: SL.NO | E14: NAME | F14: DEPARTMENT | G14: EST | H14: TOTAL DAYS | I14: MESSCUT | J14: EFFECTIVE DAYS | K14: GUEST | L14: LATE MESS | M14: EXTRAS | N14: FINAL
D15: 1 | E15: ALAN P SUNIL | F15: CIVIL | G15: =$F$9 -> 400 | H15: 26 | I15: 13 | J15: =H15-(I15*0.7) -> 16.9 | N15: =J15*$F$8+G15+M15+L15+K15 -> 1904.1
D16: =D15+1 -> 2 | E16: RAYID MUHAMMED | F16: CIVIL | G16: =$F$9 -> 400 | H16: 26 | I16: 3 | J16: =H16-(I16*0.7) -> 23.9 | L16: 5 | N16: =J16*$F$8+G16+M16+L16+K16 -> 2532.1
D17: =D16+1 -> 3 | E17: ADWAITH M | F17: CIVIL | G17: =$F$9 -> 400 | H17: 26 | I17: 3 | J17: =H17-(I17*0.7) -> 23.9 | N17: =J17*$F$8+G17+M17+L17+K17 -> 2527.1
D18: =D17+1 -> 4 | E18: FAHADH MOHAMMED M K | F18: MECH | G18: =$F$9 -> 400 | H18: 26 | I18: 8 | J18: =H18-(I18*0.7) -> 20.4 | K18: 30 | L18: 5 | N18: =J18*$F$8+G18+M18+L18+K18 -> 2250.6
D19: =D18+1 -> 5 | E19: MUHAMMED RAZAL | F19: CIVIL | G19: =$F$9 -> 400 | H19: 26 | I19: 4 | J19: =H19-(I19*0.7) -> 23.2 | L19: 10 | N19: =J19*$F$8+G19+M19+L19+K19 -> 2474.8
D20: =D19+1 -> 6 | E20: Sivaprasad | F20: CIVIL | G20: =$F$9 -> 400 | H20: 26 | I20: 4 | J20: =H20-(I20*0.7) -> 23.2 | N20: =J20*$F$8+G20+M20+L20+K20 -> 2464.8
D21: =D20+1 -> 7 | E21: Gautham sathosh ce | F21: CIVIL | G21: =$F$9 -> 400 | H21: 26 | J21: =H21-(I21*0.7) -> 26 | L21: 5 | N21: =J21*$F$8+G21+M21+L21+K21 -> 2719
D22: =D21+1 -> 8 | E22: HEFI RAHMAN | F22: CIVIL | G22: =$F$9 -> 400 | H22: 26 | I22: 3 | J22: =H22-(I22*0.7) -> 23.9 | L22: 10 | N22: =J22*$F$8+G22+M22+L22+K22 -> 2537.1
D23: =D22+1 -> 9 | E23: MOHAMMED SHAN K K | F23: CIVIL | G23: =$F$9 -> 400 | H23: 26 | I23: 4 | J23: =H23-(I23*0.7) -> 23.2 | N23: =J23*$F$8+G23+M23+L23+K23 -> 2464.8
D24: =D23+1 -> 10 | E24: Vaibhav | F24: CIVIL | G24: =$F$9 -> 400 | H24: 26 | I24: 3 | J24: =H24-(I24*0.7) -> 23.9 | K24: 45 | L24: 5 | N24: =J24*$F$8+G24+M24+L24+K24 -> 2577.1
D25: =D24+1 -> 11 | E25: KRISHNAJITH | F25: CIVIL | G25: =$F$9 -> 400 | H25: 26 | I25: 7 | J25: =H25-(I25*0.7) -> 21.1 | L25: 10 | N25: =J25*$F$8+G25+M25+L25+K25 -> 2287.9
D26: =D25+1 -> 12 | E26: RADHIN | F26: CIVIL | G26: =$F$9 -> 400 | H26: 26 | I26: 4 | J26: =H26-(I26*0.7) -> 23.2 | L26: 25 | N26: =J26*$F$8+G26+M26+L26+K26 -> 2489.8
D27: =D26+1 -> 13 | E27: MUHAMMED RIZWAN | F27: CIVIL | G27: =$F$9 -> 400 | H27: 26 | I27: 11 | J27: =H27-(I27*0.7) -> 18.3 | L27: 15 | N27: =J27*$F$8+G27+M27+L27+K27 -> 2043.7
D28: =D27+1 -> 14 | E28: sravan | F28: CS | G28: =$F$9 -> 400 | H28: 26 | I28: 4 | J28: =H28-(I28*0.7) -> 23.2 | N28: =J28*$F$8+G28+M28+L28+K28 -> 2464.8
D29: =D28+1 -> 15 | E29: ADITH CHANDRAN A | F29: CS | G29: =$F$9 -> 400 | H29: 26 | I29: 3 | J29: =H29-(I29*0.7) -> 23.9 | K29: 225 | N29: =J29*$F$8+G29+M29+L29+K29 -> 2752.1
D30: =D29+1 -> 16 | E30: Akhil A Anand | F30: CS | G30: =$F$9 -> 400 | H30: 26 | I30: 13 | J30: =H30-(I30*0.7) -> 16.9 | K30: 95 | N30: =J30*$F$8+G30+M30+L30+K30 -> 1999.1
D31: =D30+1 -> 17 | E31: JIJIN SREEDHAR | F31: CS | G31: =$F$9 -> 400 | H31: 26 | J31: =H31-(I31*0.7) -> 26 | N31: =J31*$F$8+G31+M31+L31+K31 -> 2714
D32: =D31+1 -> 18 | E32: NANDU KRISHNA | F32: CS | G32: =$F$9 -> 400 | H32: 26 | I32: 6 | J32: =H32-(I32*0.7) -> 21.8 | K32: 40 | N32: =J32*$F$8+G32+M32+L32+K32 -> 2380.2
D33: =D32+1 -> 19 | E33: JAWAD ALI K K | F33: CS | G33: =$F$9 -> 400 | H33: 26 | I33: 3 | J33: =H33-(I33*0.7) -> 23.9 | N33: =J33*$F$8+G33+M33+L33+K33 -> 2527.1
D34: =D33+1 -> 20 | E34: VIVEK V JOSEPH | F34: CS | G34: =$F$9 -> 400 | H34: 26 | I34: 3 | J34: =H34-(I34*0.7) -> 23.9 | N34: =J34*$F$8+G34+M34+L34+K34 -> 2527.1
D35: =D34+1 -> 21 | E35: RAYHAN K N | F35: CS | G35: =$F$9 -> 400 | H35: 26 | I35: 4 | J35: =H35-(I35*0.7) -> 23.2 | L35: 10 | N35: =J35*$F$8+G35+M35+L35+K35 -> 2474.8
D36: =D35+1 -> 22 | E36: SANIN ROSHAN A | F36: CS | G36: =$F$9 -> 400 | H36: 26 | J36: =H36-(I36*0.7) -> 26 | N36: =J36*$F$8+G36+M36+L36+K36 -> 2714
D37: =D36+1 -> 23 | E37: Sebin Thomas | F37: CS | G37: =$F$9 -> 400 | H37: 26 | I37: 9 | J37: =H37-(I37*0.7) -> 19.7 | N37: =J37*$F$8+G37+M37+L37+K37 -> 2153.3
D38: =D37+1 -> 24 | E38: HARINANDAN | F38: CS | G38: =$F$9 -> 400 | H38: 26 | I38: 7 | J38: =H38-(I38*0.7) -> 21.1 | N38: =J38*$F$8+G38+M38+L38+K38 -> 2277.9
D39: =D38+1 -> 25 | E39: Sebin Babu P | F39: CS | G39: =$F$9 -> 400 | H39: 26 | J39: =H39-(I39*0.7) -> 26 | N39: =J39*$F$8+G39+M39+L39+K39 -> 2714
D40: =D39+1 -> 26 | E40: RHITHUJITH | F40: CS | G40: =$F$9 -> 400 | H40: 26 | J40: =H40-(I40*0.7) -> 26 | N40: =J40*$F$8+G40+M40+L40+K40 -> 2714
D41: =D40+1 -> 27 | E41: Vishnu mk | F41: CSE | G41: =$F$9 -> 400 | H41: 26 | I41: 7 | J41: =H41-(I41*0.7) -> 21.1 | N41: =J41*$F$8+G41+M41+L41+K41 -> 2277.9
D42: =D41+1 -> 28 | E42: Vishnu PM | F42: CSE | G42: =$F$9 -> 400 | H42: 26 | I42: 3 | J42: =H42-(I42*0.7) -> 23.9 | N42: =J42*$F$8+G42+M42+L42+K42 -> 2527.1
D43: =D42+1 -> 29 | E43: Abhiram S | F43: CSE | G43: =$F$9 -> 400 | H43: 26 | I43: 12 | J43: =H43-(I43*0.7) -> 17.6 | N43: =J43*$F$8+G43+M43+L43+K43 -> 1966.4
D44: =D43+1 -> 30 | E44: Eldho Alias | F44: CSE | G44: =$F$9 -> 400 | H44: 26 | I44: 7 | J44: =H44-(I44*0.7) -> 21.1 | N44: =J44*$F$8+G44+M44+L44+K44 -> 2277.9
D45: =D44+1 -> 31 | E45: Gautham P Raj | F45: CSE | G45: =$F$9 -> 400 | H45: 26 | I45: 6 | J45: =H45-(I45*0.7) -> 21.8 | N45: =J45*$F$8+G45+M45+L45+K45 -> 2340.2
...

Sheet Sheet3
B2: lm
A3: devarashan | B3: 7
A4: anjo shaju | B4: 5
A5: karan
A6: nabeel | B6: 2
A7: misab
A8: basil | B8: 2
A9: abhishek us | B9: 11
A10: rohan k | B10: 2
A11: anadharam
A12: ajay
A13: nandakishor | B13: 2
A14: rahul dev | B14: 8
A15: sinoj | B15: 4
A16: ashish | B16: 4
A17: ajay
A18: amjad(mech)
A19: amal a | B19: 4
A20: unni r | B20: 3
A21: sayooj p
A22: shyam prakash | B22: 4
A23: prashob | B23: 2
A24: anshad | B24: 4
A25: krishnahari | B25: 5
A26: amjad(dcs) | B26: 2
A27: shahab ahmmed | B27: 3
A28: muhsin ali
A29: bendavid | B29: 4
A30: mu shan
A31: rayid
A32: adonis j | B32: 2
A33: joseph(mech)
A34: binyamin
A35: aswin sa | B35: 3
A36: rishin ragesh
A37: thanver ali | B37: 5
A38: joyel jhony
A39: nufaih | B39: 4
A40: adeeb rahman | B40: 6
A41: christo thomas | B41: 4
...
